package com.advance.mistra.test.juc.future;

import java.util.concurrent.*;

/**
 * @author Mistra
 * @ Version: 1.0
 * @ Time: 2020/3/29 10:51
 * @ Description: 演示get方法过程中抛出异常，for循环为了演示抛出Exception的时机：并不是说一产生异常就抛出，直到我们get执行时，才会抛出。
 * @ Copyright (c) Mistra,All Rights Reserved.
 * @ Github: https://github.com/MistraR
 * @ CSDN: https://blog.csdn.net/axela30w
 */
public class FutureException {

    public static void main(String[] args) {
        ExecutorService service = Executors.newFixedThreadPool(20);
        Future<Integer> future = service.submit(new CallableTask());

        try {
            for (int i = 0; i < 5; i++) {
                System.out.println(i);
                Thread.sleep(500);
            }
            System.out.println(future.isDone());
            future.get();
        } catch (InterruptedException e) {
            e.printStackTrace();
            System.out.println("InterruptedException异常");
        } catch (ExecutionException e) {
            e.printStackTrace();
            System.out.println("ExecutionException异常");
        }
    }

    static class CallableTask implements Callable<Integer> {
        @Override
        public Integer call() throws Exception {
            throw new IllegalArgumentException("Callable抛出异常");
        }
    }
}
